{
 "cells": [
  {
   "cell_type": "code",
   "execution_count": 2,
   "metadata": {},
   "outputs": [
    {
     "name": "stderr",
     "output_type": "stream",
     "text": [
      "Using TensorFlow backend.\n",
      "ERROR:root:Internal Python error in the inspect module.\n",
      "Below is the traceback from this internal error.\n",
      "\n"
     ]
    },
    {
     "name": "stdout",
     "output_type": "stream",
     "text": [
      "Traceback (most recent call last):\n",
      "  File \"c:\\users\\student\\anaconda3\\envs\\py36\\lib\\site-packages\\IPython\\core\\interactiveshell.py\", line 3331, in run_code\n",
      "    exec(code_obj, self.user_global_ns, self.user_ns)\n",
      "  File \"<ipython-input-2-3b65c519c7b1>\", line 1, in <module>\n",
      "    from keras.datasets import mnist\n",
      "  File \"c:\\users\\student\\anaconda3\\envs\\py36\\lib\\site-packages\\keras\\__init__.py\", line 3, in <module>\n",
      "    from . import utils\n",
      "  File \"c:\\users\\student\\anaconda3\\envs\\py36\\lib\\site-packages\\keras\\utils\\__init__.py\", line 6, in <module>\n",
      "    from . import conv_utils\n",
      "  File \"c:\\users\\student\\anaconda3\\envs\\py36\\lib\\site-packages\\keras\\utils\\conv_utils.py\", line 9, in <module>\n",
      "    from .. import backend as K\n",
      "  File \"c:\\users\\student\\anaconda3\\envs\\py36\\lib\\site-packages\\keras\\backend\\__init__.py\", line 87, in <module>\n",
      "    from .tensorflow_backend import *\n",
      "  File \"c:\\users\\student\\anaconda3\\envs\\py36\\lib\\site-packages\\keras\\backend\\tensorflow_backend.py\", line 357, in <module>\n",
      "    name_scope = tf.name_scope\n",
      "  File \"c:\\users\\student\\anaconda3\\envs\\py36\\lib\\site-packages\\tensorflow_core\\python\\util\\module_wrapper.py\", line 193, in __getattr__\n",
      "    attr = getattr(self._tfmw_wrapped_module, name)\n",
      "AttributeError: module 'tensorflow' has no attribute 'name_scope'\n",
      "\n",
      "During handling of the above exception, another exception occurred:\n",
      "\n",
      "Traceback (most recent call last):\n",
      "  File \"c:\\users\\student\\anaconda3\\envs\\py36\\lib\\site-packages\\IPython\\core\\interactiveshell.py\", line 2044, in showtraceback\n",
      "    stb = value._render_traceback_()\n",
      "AttributeError: 'AttributeError' object has no attribute '_render_traceback_'\n",
      "\n",
      "During handling of the above exception, another exception occurred:\n",
      "\n",
      "Traceback (most recent call last):\n",
      "  File \"c:\\users\\student\\anaconda3\\envs\\py36\\lib\\site-packages\\IPython\\core\\ultratb.py\", line 1148, in get_records\n",
      "    return _fixed_getinnerframes(etb, number_of_lines_of_context, tb_offset)\n",
      "  File \"c:\\users\\student\\anaconda3\\envs\\py36\\lib\\site-packages\\IPython\\core\\ultratb.py\", line 316, in wrapped\n",
      "    return f(*args, **kwargs)\n",
      "  File \"c:\\users\\student\\anaconda3\\envs\\py36\\lib\\site-packages\\IPython\\core\\ultratb.py\", line 350, in _fixed_getinnerframes\n",
      "    records = fix_frame_records_filenames(inspect.getinnerframes(etb, context))\n",
      "  File \"c:\\users\\student\\anaconda3\\envs\\py36\\lib\\inspect.py\", line 1490, in getinnerframes\n",
      "    frameinfo = (tb.tb_frame,) + getframeinfo(tb, context)\n",
      "  File \"c:\\users\\student\\anaconda3\\envs\\py36\\lib\\inspect.py\", line 1448, in getframeinfo\n",
      "    filename = getsourcefile(frame) or getfile(frame)\n",
      "  File \"c:\\users\\student\\anaconda3\\envs\\py36\\lib\\inspect.py\", line 696, in getsourcefile\n",
      "    if getattr(getmodule(object, filename), '__loader__', None) is not None:\n",
      "  File \"c:\\users\\student\\anaconda3\\envs\\py36\\lib\\inspect.py\", line 733, in getmodule\n",
      "    if ismodule(module) and hasattr(module, '__file__'):\n",
      "  File \"c:\\users\\student\\anaconda3\\envs\\py36\\lib\\site-packages\\tensorflow\\__init__.py\", line 50, in __getattr__\n",
      "    module = self._load()\n",
      "  File \"c:\\users\\student\\anaconda3\\envs\\py36\\lib\\site-packages\\tensorflow\\__init__.py\", line 44, in _load\n",
      "    module = _importlib.import_module(self.__name__)\n",
      "  File \"c:\\users\\student\\anaconda3\\envs\\py36\\lib\\importlib\\__init__.py\", line 126, in import_module\n",
      "    return _bootstrap._gcd_import(name[level:], package, level)\n",
      "  File \"<frozen importlib._bootstrap>\", line 994, in _gcd_import\n",
      "  File \"<frozen importlib._bootstrap>\", line 971, in _find_and_load\n",
      "  File \"<frozen importlib._bootstrap>\", line 941, in _find_and_load_unlocked\n",
      "  File \"<frozen importlib._bootstrap>\", line 219, in _call_with_frames_removed\n",
      "  File \"<frozen importlib._bootstrap>\", line 994, in _gcd_import\n",
      "  File \"<frozen importlib._bootstrap>\", line 971, in _find_and_load\n",
      "  File \"<frozen importlib._bootstrap>\", line 955, in _find_and_load_unlocked\n",
      "  File \"<frozen importlib._bootstrap>\", line 665, in _load_unlocked\n",
      "  File \"<frozen importlib._bootstrap_external>\", line 678, in exec_module\n",
      "  File \"<frozen importlib._bootstrap>\", line 219, in _call_with_frames_removed\n",
      "  File \"c:\\users\\student\\anaconda3\\envs\\py36\\lib\\site-packages\\tensorflow_core\\__init__.py\", line 36, in <module>\n",
      "    from tensorflow._api.v1 import compat\n",
      "  File \"c:\\users\\student\\anaconda3\\envs\\py36\\lib\\site-packages\\tensorflow_core\\_api\\v1\\compat\\__init__.py\", line 23, in <module>\n",
      "    from tensorflow._api.v1.compat import v1\n",
      "  File \"c:\\users\\student\\anaconda3\\envs\\py36\\lib\\site-packages\\tensorflow_core\\_api\\v1\\compat\\v1\\__init__.py\", line 41, in <module>\n",
      "    from tensorflow._api.v1.compat.v1 import feature_column\n",
      "  File \"c:\\users\\student\\anaconda3\\envs\\py36\\lib\\site-packages\\tensorflow_core\\_api\\v1\\compat\\v1\\feature_column\\__init__.py\", line 10, in <module>\n",
      "    from tensorflow.python.feature_column.feature_column import input_layer\n",
      "  File \"c:\\users\\student\\anaconda3\\envs\\py36\\lib\\site-packages\\tensorflow_core\\python\\feature_column\\feature_column.py\", line 148, in <module>\n",
      "    from tensorflow.python.layers import base\n",
      "  File \"c:\\users\\student\\anaconda3\\envs\\py36\\lib\\site-packages\\tensorflow_core\\python\\layers\\base.py\", line 25, in <module>\n",
      "    from tensorflow.python.keras import backend\n",
      "  File \"c:\\users\\student\\anaconda3\\envs\\py36\\lib\\site-packages\\tensorflow_core\\python\\keras\\__init__.py\", line 27, in <module>\n",
      "    from tensorflow.python.keras import applications\n",
      "  File \"c:\\users\\student\\anaconda3\\envs\\py36\\lib\\site-packages\\tensorflow_core\\python\\keras\\applications\\__init__.py\", line 53, in <module>\n",
      "    from tensorflow.python.keras.applications.densenet import DenseNet121\n",
      "  File \"c:\\users\\student\\anaconda3\\envs\\py36\\lib\\site-packages\\tensorflow_core\\python\\keras\\applications\\densenet.py\", line 22, in <module>\n",
      "    from keras_applications import densenet\n",
      "  File \"c:\\users\\student\\anaconda3\\envs\\py36\\lib\\site-packages\\keras_applications\\densenet.py\", line 23, in <module>\n",
      "    backend = get_keras_submodule('backend')\n",
      "  File \"c:\\users\\student\\anaconda3\\envs\\py36\\lib\\site-packages\\keras_applications\\__init__.py\", line 34, in get_keras_submodule\n",
      "    raise ImportError('You need to first `import keras` '\n",
      "ImportError: You need to first `import keras` in order to use `keras_applications`. For instance, you can do:\n",
      "\n",
      "```\n",
      "import keras\n",
      "from keras_applications import vgg16\n",
      "```\n",
      "\n",
      "Or, preferably, this equivalent formulation:\n",
      "\n",
      "```\n",
      "from keras import applications\n",
      "```\n",
      "\n"
     ]
    },
    {
     "ename": "AttributeError",
     "evalue": "module 'tensorflow' has no attribute 'name_scope'",
     "output_type": "error",
     "traceback": [
      "\u001b[1;31m---------------------------------------------------------------------------\u001b[0m"
     ]
    }
   ],
   "source": [
    "from keras.datasets import mnist\n",
    "(train_images, train_labels), (test_images, test_labels) = mnist.load_data()"
   ]
  },
  {
   "cell_type": "code",
   "execution_count": 3,
   "metadata": {},
   "outputs": [
    {
     "name": "stderr",
     "output_type": "stream",
     "text": [
      "Using TensorFlow backend.\n",
      "ERROR:root:Internal Python error in the inspect module.\n",
      "Below is the traceback from this internal error.\n",
      "\n"
     ]
    },
    {
     "name": "stdout",
     "output_type": "stream",
     "text": [
      "Traceback (most recent call last):\n",
      "  File \"c:\\users\\student\\anaconda3\\envs\\py36\\lib\\site-packages\\IPython\\core\\interactiveshell.py\", line 3331, in run_code\n",
      "    exec(code_obj, self.user_global_ns, self.user_ns)\n",
      "  File \"<ipython-input-3-569cb3eb0b11>\", line 1, in <module>\n",
      "    from keras import models\n",
      "  File \"c:\\users\\student\\anaconda3\\envs\\py36\\lib\\site-packages\\keras\\__init__.py\", line 3, in <module>\n",
      "    from . import utils\n",
      "  File \"c:\\users\\student\\anaconda3\\envs\\py36\\lib\\site-packages\\keras\\utils\\__init__.py\", line 6, in <module>\n",
      "    from . import conv_utils\n",
      "  File \"c:\\users\\student\\anaconda3\\envs\\py36\\lib\\site-packages\\keras\\utils\\conv_utils.py\", line 9, in <module>\n",
      "    from .. import backend as K\n",
      "  File \"c:\\users\\student\\anaconda3\\envs\\py36\\lib\\site-packages\\keras\\backend\\__init__.py\", line 87, in <module>\n",
      "    from .tensorflow_backend import *\n",
      "  File \"c:\\users\\student\\anaconda3\\envs\\py36\\lib\\site-packages\\keras\\backend\\tensorflow_backend.py\", line 357, in <module>\n",
      "    name_scope = tf.name_scope\n",
      "  File \"c:\\users\\student\\anaconda3\\envs\\py36\\lib\\site-packages\\tensorflow_core\\python\\util\\module_wrapper.py\", line 193, in __getattr__\n",
      "    attr = getattr(self._tfmw_wrapped_module, name)\n",
      "AttributeError: module 'tensorflow' has no attribute 'name_scope'\n",
      "\n",
      "During handling of the above exception, another exception occurred:\n",
      "\n",
      "Traceback (most recent call last):\n",
      "  File \"c:\\users\\student\\anaconda3\\envs\\py36\\lib\\site-packages\\IPython\\core\\interactiveshell.py\", line 2044, in showtraceback\n",
      "    stb = value._render_traceback_()\n",
      "AttributeError: 'AttributeError' object has no attribute '_render_traceback_'\n",
      "\n",
      "During handling of the above exception, another exception occurred:\n",
      "\n",
      "Traceback (most recent call last):\n",
      "  File \"c:\\users\\student\\anaconda3\\envs\\py36\\lib\\site-packages\\IPython\\core\\ultratb.py\", line 1148, in get_records\n",
      "    return _fixed_getinnerframes(etb, number_of_lines_of_context, tb_offset)\n",
      "  File \"c:\\users\\student\\anaconda3\\envs\\py36\\lib\\site-packages\\IPython\\core\\ultratb.py\", line 316, in wrapped\n",
      "    return f(*args, **kwargs)\n",
      "  File \"c:\\users\\student\\anaconda3\\envs\\py36\\lib\\site-packages\\IPython\\core\\ultratb.py\", line 350, in _fixed_getinnerframes\n",
      "    records = fix_frame_records_filenames(inspect.getinnerframes(etb, context))\n",
      "  File \"c:\\users\\student\\anaconda3\\envs\\py36\\lib\\inspect.py\", line 1490, in getinnerframes\n",
      "    frameinfo = (tb.tb_frame,) + getframeinfo(tb, context)\n",
      "  File \"c:\\users\\student\\anaconda3\\envs\\py36\\lib\\inspect.py\", line 1448, in getframeinfo\n",
      "    filename = getsourcefile(frame) or getfile(frame)\n",
      "  File \"c:\\users\\student\\anaconda3\\envs\\py36\\lib\\inspect.py\", line 696, in getsourcefile\n",
      "    if getattr(getmodule(object, filename), '__loader__', None) is not None:\n",
      "  File \"c:\\users\\student\\anaconda3\\envs\\py36\\lib\\inspect.py\", line 733, in getmodule\n",
      "    if ismodule(module) and hasattr(module, '__file__'):\n",
      "  File \"c:\\users\\student\\anaconda3\\envs\\py36\\lib\\site-packages\\tensorflow\\__init__.py\", line 50, in __getattr__\n",
      "    module = self._load()\n",
      "  File \"c:\\users\\student\\anaconda3\\envs\\py36\\lib\\site-packages\\tensorflow\\__init__.py\", line 44, in _load\n",
      "    module = _importlib.import_module(self.__name__)\n",
      "  File \"c:\\users\\student\\anaconda3\\envs\\py36\\lib\\importlib\\__init__.py\", line 126, in import_module\n",
      "    return _bootstrap._gcd_import(name[level:], package, level)\n",
      "  File \"<frozen importlib._bootstrap>\", line 994, in _gcd_import\n",
      "  File \"<frozen importlib._bootstrap>\", line 971, in _find_and_load\n",
      "  File \"<frozen importlib._bootstrap>\", line 941, in _find_and_load_unlocked\n",
      "  File \"<frozen importlib._bootstrap>\", line 219, in _call_with_frames_removed\n",
      "  File \"<frozen importlib._bootstrap>\", line 994, in _gcd_import\n",
      "  File \"<frozen importlib._bootstrap>\", line 971, in _find_and_load\n",
      "  File \"<frozen importlib._bootstrap>\", line 955, in _find_and_load_unlocked\n",
      "  File \"<frozen importlib._bootstrap>\", line 665, in _load_unlocked\n",
      "  File \"<frozen importlib._bootstrap_external>\", line 678, in exec_module\n",
      "  File \"<frozen importlib._bootstrap>\", line 219, in _call_with_frames_removed\n",
      "  File \"c:\\users\\student\\anaconda3\\envs\\py36\\lib\\site-packages\\tensorflow_core\\__init__.py\", line 36, in <module>\n",
      "    from tensorflow._api.v1 import compat\n",
      "  File \"c:\\users\\student\\anaconda3\\envs\\py36\\lib\\site-packages\\tensorflow_core\\_api\\v1\\compat\\__init__.py\", line 23, in <module>\n",
      "    from tensorflow._api.v1.compat import v1\n",
      "  File \"c:\\users\\student\\anaconda3\\envs\\py36\\lib\\site-packages\\tensorflow_core\\_api\\v1\\compat\\v1\\__init__.py\", line 41, in <module>\n",
      "    from tensorflow._api.v1.compat.v1 import feature_column\n",
      "  File \"c:\\users\\student\\anaconda3\\envs\\py36\\lib\\site-packages\\tensorflow_core\\_api\\v1\\compat\\v1\\feature_column\\__init__.py\", line 10, in <module>\n",
      "    from tensorflow.python.feature_column.feature_column import input_layer\n",
      "  File \"c:\\users\\student\\anaconda3\\envs\\py36\\lib\\site-packages\\tensorflow_core\\python\\feature_column\\feature_column.py\", line 148, in <module>\n",
      "    from tensorflow.python.layers import base\n",
      "  File \"c:\\users\\student\\anaconda3\\envs\\py36\\lib\\site-packages\\tensorflow_core\\python\\layers\\base.py\", line 25, in <module>\n",
      "    from tensorflow.python.keras import backend\n",
      "  File \"c:\\users\\student\\anaconda3\\envs\\py36\\lib\\site-packages\\tensorflow_core\\python\\keras\\__init__.py\", line 27, in <module>\n",
      "    from tensorflow.python.keras import applications\n",
      "  File \"c:\\users\\student\\anaconda3\\envs\\py36\\lib\\site-packages\\tensorflow_core\\python\\keras\\applications\\__init__.py\", line 53, in <module>\n",
      "    from tensorflow.python.keras.applications.densenet import DenseNet121\n",
      "  File \"c:\\users\\student\\anaconda3\\envs\\py36\\lib\\site-packages\\tensorflow_core\\python\\keras\\applications\\densenet.py\", line 22, in <module>\n",
      "    from keras_applications import densenet\n",
      "  File \"c:\\users\\student\\anaconda3\\envs\\py36\\lib\\site-packages\\keras_applications\\densenet.py\", line 23, in <module>\n",
      "    backend = get_keras_submodule('backend')\n",
      "  File \"c:\\users\\student\\anaconda3\\envs\\py36\\lib\\site-packages\\keras_applications\\__init__.py\", line 34, in get_keras_submodule\n",
      "    raise ImportError('You need to first `import keras` '\n",
      "ImportError: You need to first `import keras` in order to use `keras_applications`. For instance, you can do:\n",
      "\n",
      "```\n",
      "import keras\n",
      "from keras_applications import vgg16\n",
      "```\n",
      "\n",
      "Or, preferably, this equivalent formulation:\n",
      "\n",
      "```\n",
      "from keras import applications\n",
      "```\n",
      "\n"
     ]
    },
    {
     "ename": "AttributeError",
     "evalue": "module 'tensorflow' has no attribute 'name_scope'",
     "output_type": "error",
     "traceback": [
      "\u001b[1;31m---------------------------------------------------------------------------\u001b[0m"
     ]
    }
   ],
   "source": [
    "from keras import models\n",
    "from keras import layers\n",
    "\n",
    "network = models.Sequential()\n",
    "network.add(layers.Dense(512, activation='relu', input_shape=(28*28,)))\n",
    "network.add(layers.Dense(10, activation='softmax'))"
   ]
  },
  {
   "cell_type": "code",
   "execution_count": 4,
   "metadata": {},
   "outputs": [
    {
     "name": "stderr",
     "output_type": "stream",
     "text": [
      "ERROR:root:Internal Python error in the inspect module.\n",
      "Below is the traceback from this internal error.\n",
      "\n"
     ]
    },
    {
     "name": "stdout",
     "output_type": "stream",
     "text": [
      "Traceback (most recent call last):\n",
      "  File \"c:\\users\\student\\anaconda3\\envs\\py36\\lib\\site-packages\\IPython\\core\\interactiveshell.py\", line 3331, in run_code\n",
      "    exec(code_obj, self.user_global_ns, self.user_ns)\n",
      "  File \"<ipython-input-4-194c59d5b87b>\", line 1, in <module>\n",
      "    network.compile(optimizer='rmsprop',\n",
      "NameError: name 'network' is not defined\n",
      "\n",
      "During handling of the above exception, another exception occurred:\n",
      "\n",
      "Traceback (most recent call last):\n",
      "  File \"c:\\users\\student\\anaconda3\\envs\\py36\\lib\\site-packages\\IPython\\core\\interactiveshell.py\", line 2044, in showtraceback\n",
      "    stb = value._render_traceback_()\n",
      "AttributeError: 'NameError' object has no attribute '_render_traceback_'\n",
      "\n",
      "During handling of the above exception, another exception occurred:\n",
      "\n",
      "Traceback (most recent call last):\n",
      "  File \"c:\\users\\student\\anaconda3\\envs\\py36\\lib\\site-packages\\IPython\\core\\ultratb.py\", line 1148, in get_records\n",
      "    return _fixed_getinnerframes(etb, number_of_lines_of_context, tb_offset)\n",
      "  File \"c:\\users\\student\\anaconda3\\envs\\py36\\lib\\site-packages\\IPython\\core\\ultratb.py\", line 316, in wrapped\n",
      "    return f(*args, **kwargs)\n",
      "  File \"c:\\users\\student\\anaconda3\\envs\\py36\\lib\\site-packages\\IPython\\core\\ultratb.py\", line 350, in _fixed_getinnerframes\n",
      "    records = fix_frame_records_filenames(inspect.getinnerframes(etb, context))\n",
      "  File \"c:\\users\\student\\anaconda3\\envs\\py36\\lib\\inspect.py\", line 1490, in getinnerframes\n",
      "    frameinfo = (tb.tb_frame,) + getframeinfo(tb, context)\n",
      "  File \"c:\\users\\student\\anaconda3\\envs\\py36\\lib\\inspect.py\", line 1448, in getframeinfo\n",
      "    filename = getsourcefile(frame) or getfile(frame)\n",
      "  File \"c:\\users\\student\\anaconda3\\envs\\py36\\lib\\inspect.py\", line 696, in getsourcefile\n",
      "    if getattr(getmodule(object, filename), '__loader__', None) is not None:\n",
      "  File \"c:\\users\\student\\anaconda3\\envs\\py36\\lib\\inspect.py\", line 733, in getmodule\n",
      "    if ismodule(module) and hasattr(module, '__file__'):\n",
      "  File \"c:\\users\\student\\anaconda3\\envs\\py36\\lib\\site-packages\\tensorflow\\__init__.py\", line 50, in __getattr__\n",
      "    module = self._load()\n",
      "  File \"c:\\users\\student\\anaconda3\\envs\\py36\\lib\\site-packages\\tensorflow\\__init__.py\", line 44, in _load\n",
      "    module = _importlib.import_module(self.__name__)\n",
      "  File \"c:\\users\\student\\anaconda3\\envs\\py36\\lib\\importlib\\__init__.py\", line 126, in import_module\n",
      "    return _bootstrap._gcd_import(name[level:], package, level)\n",
      "  File \"<frozen importlib._bootstrap>\", line 994, in _gcd_import\n",
      "  File \"<frozen importlib._bootstrap>\", line 971, in _find_and_load\n",
      "  File \"<frozen importlib._bootstrap>\", line 941, in _find_and_load_unlocked\n",
      "  File \"<frozen importlib._bootstrap>\", line 219, in _call_with_frames_removed\n",
      "  File \"<frozen importlib._bootstrap>\", line 994, in _gcd_import\n",
      "  File \"<frozen importlib._bootstrap>\", line 971, in _find_and_load\n",
      "  File \"<frozen importlib._bootstrap>\", line 955, in _find_and_load_unlocked\n",
      "  File \"<frozen importlib._bootstrap>\", line 665, in _load_unlocked\n",
      "  File \"<frozen importlib._bootstrap_external>\", line 678, in exec_module\n",
      "  File \"<frozen importlib._bootstrap>\", line 219, in _call_with_frames_removed\n",
      "  File \"c:\\users\\student\\anaconda3\\envs\\py36\\lib\\site-packages\\tensorflow_core\\__init__.py\", line 36, in <module>\n",
      "    from tensorflow._api.v1 import compat\n",
      "  File \"c:\\users\\student\\anaconda3\\envs\\py36\\lib\\site-packages\\tensorflow_core\\_api\\v1\\compat\\__init__.py\", line 23, in <module>\n",
      "    from tensorflow._api.v1.compat import v1\n",
      "  File \"c:\\users\\student\\anaconda3\\envs\\py36\\lib\\site-packages\\tensorflow_core\\_api\\v1\\compat\\v1\\__init__.py\", line 41, in <module>\n",
      "    from tensorflow._api.v1.compat.v1 import feature_column\n",
      "  File \"c:\\users\\student\\anaconda3\\envs\\py36\\lib\\site-packages\\tensorflow_core\\_api\\v1\\compat\\v1\\feature_column\\__init__.py\", line 10, in <module>\n",
      "    from tensorflow.python.feature_column.feature_column import input_layer\n",
      "  File \"c:\\users\\student\\anaconda3\\envs\\py36\\lib\\site-packages\\tensorflow_core\\python\\feature_column\\feature_column.py\", line 148, in <module>\n",
      "    from tensorflow.python.layers import base\n",
      "  File \"c:\\users\\student\\anaconda3\\envs\\py36\\lib\\site-packages\\tensorflow_core\\python\\layers\\base.py\", line 25, in <module>\n",
      "    from tensorflow.python.keras import backend\n",
      "  File \"c:\\users\\student\\anaconda3\\envs\\py36\\lib\\site-packages\\tensorflow_core\\python\\keras\\__init__.py\", line 27, in <module>\n",
      "    from tensorflow.python.keras import applications\n",
      "  File \"c:\\users\\student\\anaconda3\\envs\\py36\\lib\\site-packages\\tensorflow_core\\python\\keras\\applications\\__init__.py\", line 53, in <module>\n",
      "    from tensorflow.python.keras.applications.densenet import DenseNet121\n",
      "  File \"c:\\users\\student\\anaconda3\\envs\\py36\\lib\\site-packages\\tensorflow_core\\python\\keras\\applications\\densenet.py\", line 22, in <module>\n",
      "    from keras_applications import densenet\n",
      "  File \"c:\\users\\student\\anaconda3\\envs\\py36\\lib\\site-packages\\keras_applications\\densenet.py\", line 23, in <module>\n",
      "    backend = get_keras_submodule('backend')\n",
      "  File \"c:\\users\\student\\anaconda3\\envs\\py36\\lib\\site-packages\\keras_applications\\__init__.py\", line 34, in get_keras_submodule\n",
      "    raise ImportError('You need to first `import keras` '\n",
      "ImportError: You need to first `import keras` in order to use `keras_applications`. For instance, you can do:\n",
      "\n",
      "```\n",
      "import keras\n",
      "from keras_applications import vgg16\n",
      "```\n",
      "\n",
      "Or, preferably, this equivalent formulation:\n",
      "\n",
      "```\n",
      "from keras import applications\n",
      "```\n",
      "\n"
     ]
    },
    {
     "ename": "NameError",
     "evalue": "name 'network' is not defined",
     "output_type": "error",
     "traceback": [
      "\u001b[1;31m---------------------------------------------------------------------------\u001b[0m"
     ]
    }
   ],
   "source": [
    "network.compile(optimizer='rmsprop',\n",
    "               loss='categorical_crossentropy',\n",
    "               metrics=['accuracy'])"
   ]
  },
  {
   "cell_type": "code",
   "execution_count": null,
   "metadata": {},
   "outputs": [],
   "source": []
  }
 ],
 "metadata": {
  "kernelspec": {
   "display_name": "Python 3",
   "language": "python",
   "name": "python3"
  },
  "language_info": {
   "codemirror_mode": {
    "name": "ipython",
    "version": 3
   },
   "file_extension": ".py",
   "mimetype": "text/x-python",
   "name": "python",
   "nbconvert_exporter": "python",
   "pygments_lexer": "ipython3",
   "version": "3.6.10"
  }
 },
 "nbformat": 4,
 "nbformat_minor": 2
}
